<?xml version="1.0" ?>
<robot name="mini_cheetah" xmlns:xacro="http://ros.org/wiki/xacro">



<!--!!!!!!!!!!!!!!!!!!BODY!!!!!!!!!!!!!!!!!!!!!!!!!!!!!!!-->
  <link name="body">
        <inertial>
            <mass value="3.3"/>
            <origin xyz="0.0 0.0 0.0"/>
            <inertia ixx="0.011253" ixy="0" ixz="0" iyy="0.036203" iyz="0" izz="0.042673"/>
        </inertial>
	<visual>
            <geometry>
                <mesh filename="meshes/mini_body.stl"/>
            </geometry>
            <origin rpy="0.0 0.0 0.0" xyz="0.0 0.0 0.0"/>
        </visual>
        <!--visual>
            <geometry>
	      <box size="0.23 0.19 0.1"/>
            </geometry>
            <origin rpy="0.0 0.0 0.0" xyz="0.0 0.0 0.0"/>
        </visual-->
        <collision>
            <geometry>
              <!--mesh filename="meshes/mini_body.obj"/-->
	      <box size="0.23 0.19 0.1"/>
            </geometry>
            <origin rpy="0 0 0" xyz="0 0 0"/>
        </collision>
    </link>



<!--!!!!!!!!!!!! Front Left Leg !!!!!!!!!!!!!!!!!!!!!!!!!!!!!!!!!!!!-->
    <joint name="torso_to_abduct_fl_j" type="continuous">
        <axis xyz="1 0 0"/>
        <origin rpy="0 0 0" xyz="0.19 0.049 0.0"/>
        <parent link="body"/>
        <child link="abduct_fl"/>
	<limit effort="18" lower="-1.6" upper="1.6" velocity="40"/>
    </joint>
    <link name="abduct_fl">
        <inertial>
            <mass value="0.54"/>
            <origin xyz="0.0 0.036 0."/>
            <inertia ixx="0.000381" ixy="0.000058" ixz="0.00000045" 
                iyy="0.000560" iyz="0.00000095" izz="0.000444"/>
        </inertial>
	<visual>
            <geometry>
                <mesh filename="meshes/mini_abad.obj"/>
            </geometry>
            <origin rpy="0. 0. -1.5708" xyz="-0.055 0.0 0.0"/>
        </visual>
        <!--visual>
            <geometry>
	      <cylinder length ="0.02" radius = "0.0475"/>
            </geometry>
            <origin rpy="0. 1.5708 -1.5708" xyz="-0.055 0.0 0.0"/>
        </visual>
	<visual>
            <geometry>
	      <cylinder length ="0.06" radius = "0.0475"/>
            </geometry> 
	    <origin rpy="1.5708 0.0 0.0" xyz="0.0 0.0 0.0"/>
        </visual-->
        <collision>
            <geometry>
              <!--mesh filename="meshes/mini_abad.obj"/-->
	      <cylinder length ="0.02" radius = "0.0475"/>
            </geometry>
            <!--origin rpy="0 0 -1.5708" xyz="-0.055 0 0"/-->
	    <origin rpy="0 1.5708 -1.5708" xyz="-0.055 0.0 0.0"/>
        </collision>
	<collision>
            <geometry>
              <!--mesh filename="meshes/mini_abad.obj"/-->
	      <cylinder length ="0.06" radius = "0.0475"/>
            </geometry>
            <!--origin rpy="0 0 -1.5708" xyz="-0.055 0 0"/-->
	    <origin rpy="1.5708 0.0 0.0" xyz="0.0 0.0 0.0"/>
        </collision>
    </link>

    <joint name="abduct_fl_to_thigh_fl_j" type="continuous">
        <axis xyz="0 -1 0"/>
        <origin rpy="0.0 0.0 0.0" xyz="0.0 0.062 0.00"/>
        <parent link="abduct_fl"/>
        <child link="thigh_fl"/>
	<limit effort="18" lower="-2.6" upper="2.6" velocity="40"/>
    </joint>
    <link name="thigh_fl">
        <inertial>
            <mass value="0.634"/>
            <origin xyz="0.0 0.016 -0.02"/>
            <inertia ixx="0.001983" ixy="0.000245" ixz="0.000013" 
                iyy="0.002103" iyz="0.0000015" izz="0.000408"/>
        </inertial>
	<visual>
            <geometry>
                <mesh filename="meshes/mini_upper_link.obj"/>
            </geometry>
            <origin rpy="0.0 -1.5708 0.0" xyz="0.0 0.0 0.0"/>
        </visual>
        <!--visual>
            <geometry>
	      <cylinder length ="0.21" radius = "0.025"/>
            </geometry>
            <origin rpy="0.0 0.0 0.0" xyz="0.0 0.0 -0.105"/>
        </visual-->
        <collision>
            <geometry>
              <!--mesh filename="meshes/mini_upper_link.obj"/-->
	      <cylinder length ="0.21" radius = "0.025"/>
            </geometry>
            <origin rpy="0.0 0.0 0.0" xyz="0.0 0.0 -0.105"/>
        </collision>
    </link>

    <joint name="thigh_fl_to_knee_fl_j" type="continuous">
        <axis xyz="0 -1 0"/>
        <origin rpy="0.0 0 0.0" xyz="0.0 0.0 -0.209"/>
        <parent link="thigh_fl"/>
        <child link="shank_fl"/>
	<limit effort="26" lower="-2.6" upper="2.6" velocity="26"/>
    </joint>
    <link name="shank_fl">
        <inertial>
            <mass value="0.064"/>
            <origin xyz="0.0 0.0 -0.209"/>
            <inertia ixx="0.000245" ixy="0" ixz="0.0" iyy="0.000248" iyz="0" izz="0.000006"/>
        </inertial>
	<visual>
            <geometry>
                <mesh filename="meshes/mini_lower_link.obj"/>
            </geometry>
            <origin rpy="0.0 3.141592 0.0" xyz="0.0 0.0 0.0"/>
        </visual>
        <!--visual>
            <geometry>
	      <cylinder length ="0.19" radius = "0.015"/>
            </geometry>
            <origin rpy="0.0 3.141592 0.0" xyz="0.0 0.0 -0.095"/>
        </visual>
	<visual>
            <geometry>
              <sphere radius = "0.0175"/>
            </geometry>
            <origin rpy="0.0 3.141592 0.0" xyz="0.0 0.0 -0.195"/>
        </visual-->
        <collision>
            <geometry>
              <!--mesh filename="meshes/mini_lower_link.obj"/-->
	      <cylinder length ="0.19" radius = "0.015"/>
            </geometry>
            <origin rpy="0.0 3.141592 0.0" xyz="0 0 -0.095"/>
        </collision>
	<collision>
            <geometry>
              <!--mesh filename="meshes/mini_lower_link.obj"/-->
	      <sphere radius = "0.0175"/>
            </geometry>
            <origin rpy="0.0 3.141592 0.0" xyz="0 0 -0.195"/>
        </collision>
    </link>


    
    <!--!!!!!!!!!!!! Front Right Leg !!!!!!!!!!!!!!!!!!!!!!!!!!!!!!!!!!!!-->

    <!--!!!!Joint!!!!!!!!!!!!-->
    <joint name="torso_to_abduct_fr_j" type="continuous">
        <axis xyz="1 0 0"/>
        <origin rpy="0 0 0" xyz="0.19 -0.049 0.0"/>
        <parent link="body"/>
        <child link="abduct_fr"/>
	<limit effort="18" lower="-1.6" upper="1.6" velocity="40"/>
    </joint>
    <link name="abduct_fr">
        <inertial>
            <mass value="0.54"/>
            <origin xyz="0.0 0.036 0."/>
            <inertia ixx="0.000381" ixy="0.000058" ixz="0.00000045" 
                iyy="0.000560" iyz="0.00000095" izz="0.000444"/>
        </inertial>
	    <visual>
            <geometry>
                <mesh filename="meshes/mini_abad.obj"/>
            </geometry>
            <origin rpy="3.141592 0.0 1.5708" xyz="-0.055 0.0 0.0"/>
        </visual>
        <!--visual>
            <geometry>        
	      <cylinder length ="0.02" radius = "0.0475"/>
            </geometry>
	    <origin rpy="3.141592 1.5708 1.5708" xyz="-0.055 0.0 0.0"/>
        </visual>
	    <visual>
            <geometry>
	      <cylinder length ="0.06" radius = "0.0475"/>
            </geometry>
	    <origin rpy="1.5708 0.0 0.0" xyz="0.0 0.0 0.0"/>
        </visual-->
        <collision>
            <geometry>
              <!--mesh filename="meshes/mini_abad.obj"/-->
	      <cylinder length ="0.02" radius = "0.0475"/>
            </geometry>
            <origin rpy="3.141592 1.5708 1.5708" xyz="-0.055 0 0"/>
        </collision>
	    <collision>
            <geometry>
              <!--mesh filename="meshes/mini_abad.obj"/-->
	      <cylinder length ="0.06" radius = "0.0475"/>
            </geometry>
            <origin rpy="1.5708 0.0 0.0" xyz="-0.055 0 0"/>
        </collision>
    </link>

    <joint name="abduct_fr_to_thigh_fr_j" type="continuous">
        <axis xyz="0 -1 0"/>
        <origin rpy="0.0 0.0 0.0" xyz="0.0 -0.062 0.00"/>
        <parent link="abduct_fr"/>
        <child link="thigh_fr"/>
	<limit effort="18" lower="-2.6" upper="2.6" velocity="40"/>
    </joint>
    <link name="thigh_fr">
        <inertial>
            <mass value="0.634"/>
            <origin xyz="0.0 0.016 -0.02"/>
            <inertia ixx="0.001983" ixy="0.000245" ixz="0.000013" 
                iyy="0.002103" iyz="0.0000015" izz="0.000408"/>
        </inertial>
	    <visual>
            <geometry>
                <mesh filename="meshes/mini_upper_link.obj"/>
            </geometry>
            <origin rpy="0.0 -1.5708 0.0" xyz="0.0 0.0 0.0"/>
        </visual>
        <!--visual>
            <geometry>
	      <cylinder length ="0.21" radius = "0.025"/>
            </geometry>
            <origin rpy="0.0 0.0 0.0" xyz="0.0 0.0 -0.105"/>
        </visual-->
        <collision>
            <geometry>
              <!--mesh filename="meshes/mini_upper_link.obj"/-->
	      <cylinder length ="0.21" radius = "0.025"/>
            </geometry>
            <origin rpy="0.0 0.0 0.0" xyz="0.0 0.0 -0.105"/>
        </collision>
    </link>

    <joint name="thigh_fr_to_knee_fr_j" type="continuous">
        <axis xyz="0 -1 0"/>
        <origin rpy="0.0 0 0.0" xyz="0.0 0.0 -0.209"/>
        <parent link="thigh_fr"/>
        <child link="shank_fr"/>
	<limit effort="26" lower="-2.6" upper="2.6" velocity="26"/>
    </joint>
    <link name="shank_fr">
        <inertial>
            <mass value="0.064"/>
            <origin xyz="0.0 0.0 -0.209"/>
            <inertia ixx="0.000245" ixy="0" ixz="0.0" iyy="0.000248" iyz="0" izz="0.000006"/>
        </inertial>
	    <visual>
            <geometry>
                <mesh filename="meshes/mini_lower_link.obj"/>
            </geometry>
            <origin rpy="0.0 3.141592 0.0" xyz="0.0 0.0 0.0"/>
        </visual>
        <!--visual>
            <geometry>
	      <cylinder length ="0.19" radius = "0.015"/>
            </geometry>
            <origin rpy="0.0 3.141592 0.0" xyz="0.0 0.0 -0.095"/>
        </visual>
	    <visual>
            <geometry>
              <sphere radius = "0.0175"/>
            </geometry>
            <origin rpy="0.0 3.141592 0.0" xyz="0.0 0.0 -0.195"/>
        </visual-->
        <collision>
            <geometry>
              <!--mesh filename="meshes/mini_lower_link.obj"/-->
	      <cylinder length ="0.19" radius = "0.015"/>
            </geometry>
            <origin rpy="0.0 3.141592 0.0" xyz="0.0 0.0 -0.095"/>
        </collision>
	<collision>
            <geometry>
              <!--mesh filename="meshes/mini_lower_link.obj"/-->
	       <sphere radius = "0.0175"/>
            </geometry>
            <origin rpy="0.0 3.141592 0" xyz="0.0 0.0 -0.195"/>
        </collision>
    </link>



<!--!!!!!!!!!!!! Hind Left Leg !!!!!!!!!!!!!!!!!!!!!!!!!!!!!!!!!!!!-->
    <joint name="torso_to_abduct_hl_j" type="continuous">
        <axis xyz="1 0 0"/>
        <origin rpy="0 0 0" xyz="-0.19 0.049 0.0"/>
        <parent link="body"/>
        <child link="abduct_hl"/>
	<limit effort="18" lower="-1.6" upper="1.6" velocity="40"/>
    </joint>
    <link name="abduct_hl">
        <inertial>
            <mass value="0.54"/>
            <origin xyz="0.0 0.036 0."/>
            <inertia ixx="0.000381" ixy="0.000058" ixz="0.00000045" 
                iyy="0.000560" iyz="0.00000095" izz="0.000444"/>
        </inertial>
	    <visual>
            <geometry>
                <mesh filename="meshes/mini_abad.obj"/>
            </geometry>
            <origin rpy="3.141592 0.0 -1.5708" xyz="0.055 0.0 0.0"/>
        </visual>
        <!-- <visual>
            <geometry>
	        <cylinder length ="0.02" radius = "0.0475"/>
            </geometry>
	    <origin rpy="3.141592 1.5708 -1.5708" xyz="0.055 0.0 0.0"/>
        </visual> -->	   
        <collision>
            <geometry>
              <!--mesh filename="meshes/mini_abad.obj"/-->
	      <cylinder length ="0.02" radius = "0.0475"/>
            </geometry>
            <origin rpy="3.141592 1.5708 -1.5708" xyz="0.055 0 0"/>
        </collision>	   
    </link>

    <joint name="abduct_hl_to_thigh_hl_j" type="continuous">
        <axis xyz="0 -1 0"/>
        <origin rpy="0.0 0.0 0.0" xyz="0.0 0.062 0.00"/>
        <parent link="abduct_hl"/>
        <child link="thigh_hl"/>
	<limit effort="18" lower="-2.6" upper="2.6" velocity="40"/>
    </joint>
    <link name="thigh_hl">
        <inertial>
            <mass value="0.634"/>
            <origin xyz="0.0 0.016 -0.02"/>
            <inertia ixx="0.001983" ixy="0.000245" ixz="0.000013" 
                iyy="0.002103" iyz="0.0000015" izz="0.000408"/>
        </inertial>
	    <visual>
            <geometry>
                <mesh filename="meshes/mini_upper_link.obj"/>
            </geometry>
            <origin rpy="0.0 -1.5708 0.0" xyz="0.0 0.0 0.0"/>
        </visual>
        <!--visual>
            <geometry>
	      <cylinder length ="0.21" radius = "0.025"/>
            </geometry>
            <origin rpy="0.0 0.0 0.0" xyz="0.0 0.0 -0.105"/>
        </visual-->
        <collision>
            <geometry>
              <!--mesh filename="meshes/mini_upper_link.obj"/-->
	      <cylinder length ="0.21" radius = "0.025"/>
            </geometry>
            <origin rpy="0.0 0.0 0.0" xyz="0.0 0.0 -0.105"/>
        </collision>
    </link>

    <joint name="thigh_hl_to_knee_hl_j" type="continuous">
        <axis xyz="0 -1 0"/>
        <origin rpy="0.0 0 0.0" xyz="0.0 0.0 -0.209"/>
        <parent link="thigh_hl"/>
        <child link="shank_hl"/>
	<limit effort="26" lower="-2.6" upper="2.6" velocity="26"/>
    </joint>
    <link name="shank_hl">
        <inertial>
            <mass value="0.064"/>
            <origin xyz="0.0 0.0 -0.209"/>
            <inertia ixx="0.000245" ixy="0" ixz="0.0" iyy="0.000248" iyz="0" izz="0.000006"/>
        </inertial>
	    <visual>
            <geometry>
                <mesh filename="meshes/mini_lower_link.obj"/>
            </geometry>
            <origin rpy="0.0 3.141592 0.0" xyz="0.0 0.0 0.0"/>
        </visual>
        <!--visual>
            <geometry>
	      <cylinder length ="0.19" radius = "0.015"/>
            </geometry>
            <origin rpy="0.0 3.141592 0.0" xyz="0.0 0.0 -0.095"/>
        </visual>
	<visual>
            <geometry>
              <sphere radius = "0.0175"/>
            </geometry>
            <origin rpy="0.0 3.141592 0.0" xyz="0.0 0.0 -0.195"/>
        </visual-->
        <collision>
            <geometry>
              <!--mesh filename="meshes/mini_lower_link.obj"/-->
	      <cylinder length ="0.19" radius = "0.015"/>
            </geometry>
            <origin rpy="0.0 3.141592 0.0" xyz="0.0 0.0 -0.095"/>
        </collision>
	<collision>
            <geometry>
               <!--mesh filename="meshes/mini_lower_link.obj"/-->
	       <sphere radius = "0.0175"/>
            </geometry>
            <origin rpy="0.0 3.141592 0.0" xyz="0.0 0.0 -0.195"/>
        </collision>
    </link>

    
<!--!!!!!!!!!!!! Hind Right Leg !!!!!!!!!!!!!!!!!!!!!!!!!!!!!!!!!!!!-->
    <joint name="torso_to_abduct_hr_j" type="continuous">
        <axis xyz="1 0 0"/>
        <origin rpy="0 0 0" xyz="-0.19 -0.049 0.0"/>
        <parent link="body"/>
        <child link="abduct_hr"/>
	<limit effort="18" lower="-1.6" upper="1.6" velocity="40"/>
    </joint>
    <link name="abduct_hr">
        <inertial>
            <mass value="0.54"/>
            <origin xyz="0.0 0.036 0."/>
            <inertia ixx="0.000381" ixy="0.000058" ixz="0.00000045" 
                iyy="0.000560" iyz="0.00000095" izz="0.000444"/>
        </inertial>
	<visual>
            <geometry>
                <mesh filename="meshes/mini_abad.obj"/>
            </geometry>
            <origin rpy="0.0 0.0 1.5708" xyz="0.055 0.0 0.0"/>
        </visual>
        <!--visual>
            <geometry>
	      <cylinder length ="0.02" radius = "0.0475"/>
            </geometry>
	    <origin rpy="0.0 1.5708 1.5708" xyz="0.055 0.0 0.0"/>
        </visual>
	<visual>
            <geometry>
	      <cylinder length ="0.06" radius = "0.0475"/>
            </geometry>
	    <origin rpy="1.5708 0.0 0.0" xyz="0.0 0.0 0.0"/>
        </visual-->
        <collision>
            <geometry>
              <!--mesh filename="meshes/mini_abad.obj"/-->
	      <cylinder length ="0.02" radius = "0.0475"/>
            </geometry>
            <origin rpy="0.0 1.5708 1.5708" xyz="0.055 0.0 0.0"/>
        </collision>
	<collision>
            <geometry>
              <!--mesh filename="meshes/mini_abad.obj"/-->
	      <cylinder length ="0.06" radius = "0.0475"/>
            </geometry>
            <origin rpy="1.5708 0.0 0.0" xyz="0.0 0.0 0.0"/>
        </collision>
    </link>

    <joint name="abduct_hr_to_thigh_hr_j" type="continuous">
        <axis xyz="0 -1 0"/>
        <origin rpy="0.0 0.0 0.0" xyz="0.0 -0.062 0.00"/>
        <parent link="abduct_hr"/>
        <child link="thigh_hr"/>
	<limit effort="18" lower="-2.6" upper="2.6" velocity="40"/>
    </joint>
    <link name="thigh_hr">
        <inertial>
            <mass value="0.634"/>
            <origin xyz="0.0 0.016 -0.02"/>
            <inertia ixx="0.001983" ixy="0.000245" ixz="0.000013" 
                iyy="0.002103" iyz="0.0000015" izz="0.000408"/>
        </inertial>
	<visual>
            <geometry>
                <mesh filename="meshes/mini_upper_link.obj"/>
            </geometry>
            <origin rpy="0.0 -1.5708 0.0" xyz="0.0 0.0 0.0"/>
        </visual>
        <!--visual>
            <geometry>
	      <cylinder length ="0.21" radius = "0.025"/>
            </geometry>
            <origin rpy="0.0 0.0 0.0" xyz="0.0 0.0 -0.105"/>
        </visual-->
        <collision>
            <geometry>
              <!--mesh filename="meshes/mini_upper_link.obj"/-->
	      <cylinder length ="0.21" radius = "0.025"/>
            </geometry>
            <origin rpy="0.0 0.0 0.0" xyz="0.0 0.0 -0.105"/>
        </collision>
    </link>

    <joint name="thigh_hr_to_knee_hr_j" type="continuous">
        <axis xyz="0 -1 0"/>
        <origin rpy="0.0 0 0.0" xyz="0.0 0.0 -0.209"/>
        <parent link="thigh_hr"/>
        <child link="shank_hr"/>
	<limit effort="26" lower="-2.6" upper="2.6" velocity="26"/>
    </joint>
    <link name="shank_hr">
        <inertial>
            <mass value="0.064"/>
            <origin xyz="0.0 0.0 -0.209"/>
            <inertia ixx="0.000245" ixy="0" ixz="0.0" iyy="0.000248" iyz="0" izz="0.000006"/>
        </inertial>
	<visual>
            <geometry>
                <mesh filename="meshes/mini_lower_link.obj"/>
            </geometry>
            <origin rpy="0.0 3.141592 0.0" xyz="0.0 0.0 0.0"/>
        </visual>
        <!--visual>
            <geometry>
	      <cylinder length ="0.19" radius = "0.015"/>
            </geometry>
            <origin rpy="0.0 3.141592 0.0" xyz="0.0 0.0 -0.095"/>
        </visual>
	<visual>
            <geometry>
              <sphere radius = "0.0175"/>
            </geometry>
            <origin rpy="0.0 3.141592 0.0" xyz="0.0 0.0 -0.195"/>
        </visual-->
        <collision>
            <geometry>
              <!--mesh filename="meshes/mini_lower_link.obj"/-->
	      <cylinder length ="0.19" radius = "0.015"/>
            </geometry>
            <origin rpy="0.0 3.141592 0.0" xyz="0 0 -0.095"/>
        </collision>
	<collision>
            <geometry>
              <!--mesh filename="meshes/mini_lower_link.obj"/-->
	      <sphere radius = "0.0175"/>
            </geometry>
            <origin rpy="0.0 3.141592 0.0" xyz="0.0 0.0 -0.195"/>
        </collision>
    </link>

</robot>
